tests/sample_test.txt
ADD 1 BUY 100 10
ADD 2 BUY 100 5
ADD 3 SELL 100 12
PRINT
TRADES

ADD 4 SELL 105 10
ADD 5 BUY 104 10
PRINT

CANCEL 4
PRINT

MODIFY 5 106 10
PRINT
TRADES

ADD 6 SELL 106 5
ADD 7 SELL 106 8
ADD 8 BUY 106 10
PRINT
TRADES

EXIT
